<?xml version="1.0" encoding="utf-8"?>
<!-- This URDF was automatically created by SolidWorks to URDF Exporter! Originally created by Stephen Brawner (brawner@gmail.com) 
     Commit Version: 1.6.0-4-g7f85cfe  Build Version: 1.6.7995.38578
     For more information, please see http://wiki.ros.org/sw_urdf_exporter -->
<robot
  name="rohm_amr_description">
  <link
    name="base_link">
    <inertial>
      <origin
        xyz="-0.073483 -0.0043519 0.24859"
        rpy="0 0 0" />
      <mass
        value="28.984" />
      <inertia
        ixx="0.30334"
        ixy="9.1593E-06"
        ixz="0.00086172"
        iyy="0.32997"
        iyz="-6.0857E-05"
        izz="0.404" />
    </inertial>
    <visual>
      <origin
        xyz="0 0 0"
        rpy="0 0 0" />
      <geometry>
        <mesh
          filename="package://rohm_amr_description/meshes/base_link.STL" />
      </geometry>
      <material
        name="">
        <color
          rgba="0.79216 0.81961 0.93333 1" />
      </material>
    </visual>
    <collision>
      <origin
        xyz="0 0 0"
        rpy="0 0 0" />
      <geometry>
        <mesh
          filename="package://rohm_amr_description/meshes/base_link.STL" />
      </geometry>
    </collision>
  </link>
  <link
    name="wheel_right_link">
    <inertial>
      <origin
        xyz="-5.1461E-18 0 -2.7756E-17"
        rpy="0 0 0" />
      <mass
        value="0.23496" />
      <inertia
        ixx="0.00026447"
        ixy="1.9667E-21"
        ixz="-1.0084E-20"
        iyy="0.00026447"
        iyz="-1.1375E-22"
        izz="0.00047658" />
    </inertial>
    <visual>
      <origin
        xyz="0 0 0"
        rpy="0 0 0" />
      <geometry>
        <mesh
          filename="package://rohm_amr_description/meshes/wheel_right_link.STL" />
      </geometry>
      <material
        name="">
        <color
          rgba="0.79216 0.81961 0.93333 1" />
      </material>
    </visual>
    <collision>
      <origin
        xyz="0 0 0"
        rpy="0 0 0" />
      <geometry>
        <mesh
          filename="package://rohm_amr_description/meshes/wheel_right_link.STL" />
      </geometry>
    </collision>
  </link>
  <joint
    name="wheel_right_joint"
    type="continuous">
    <origin
      xyz="0 -0.188 0.055"
      rpy="1.5708 0 0" />
    <parent
      link="base_link" />
    <child
      link="wheel_right_link" />
    <axis
      xyz="0 0 -1" />
    <limit
      effort="20"
      velocity="10.5" />
  </joint>
  <link
    name="wheel_left_link">
    <inertial>
      <origin
        xyz="-4.6862E-18 0 -2.7756E-17"
        rpy="0 0 0" />
      <mass
        value="0.23496" />
      <inertia
        ixx="0.00026447"
        ixy="2.309E-21"
        ixz="-1.0084E-20"
        iyy="0.00026447"
        iyz="-5.7751E-23"
        izz="0.00047658" />
    </inertial>
    <visual>
      <origin
        xyz="0 0 0"
        rpy="0 0 0" />
      <geometry>
        <mesh
          filename="package://rohm_amr_description/meshes/wheel_left_link.STL" />
      </geometry>
      <material
        name="">
        <color
          rgba="0.79216 0.81961 0.93333 1" />
      </material>
    </visual>
    <collision>
      <origin
        xyz="0 0 0"
        rpy="0 0 0" />
      <geometry>
        <mesh
          filename="package://rohm_amr_description/meshes/wheel_left_link.STL" />
      </geometry>
    </collision>
  </link>
  <joint
    name="wheel_left_joint"
    type="continuous">
    <origin
      xyz="0 0.188 0.055"
      rpy="1.5708 0 0" />
    <parent
      link="base_link" />
    <child
      link="wheel_left_link" />
    <axis
      xyz="0 0 -1" />
    <limit
      effort="20"
      velocity="10.5" />
  </joint>
  <link
    name="caster_arm_front_right_link">
    <inertial>
      <origin
        xyz="-0.0067542 2.146E-09 -0.02431"
        rpy="0 0 0" />
      <mass
        value="0.10224" />
      <inertia
        ixx="8.0517E-05"
        ixy="3.1139E-12"
        ixz="-2.0766E-05"
        iyy="8.4409E-05"
        iyz="-3.5715E-12"
        izz="6.6718E-05" />
    </inertial>
    <visual>
      <origin
        xyz="0 0 0"
        rpy="0 0 0" />
      <geometry>
        <mesh
          filename="package://rohm_amr_description/meshes/caster_arm_front_right_link.STL" />
      </geometry>
      <material
        name="">
        <color
          rgba="0.79216 0.81961 0.93333 1" />
      </material>
    </visual>
    <collision>
      <origin
        xyz="0 0 0"
        rpy="0 0 0" />
      <geometry>
        <mesh
          filename="package://rohm_amr_description/meshes/caster_arm_front_right_link.STL" />
      </geometry>
    </collision>
  </link>
  <joint
    name="caster_arm_front_right_joint"
    type="continuous">
    <origin
      xyz="0.3775 -0.16 0.107"
      rpy="0 0 0" />
    <parent
      link="base_link" />
    <child
      link="caster_arm_front_right_link" />
    <axis
      xyz="0 0 1" />
  </joint>
  <link
    name="caster_wheel_front_right_link">
    <inertial>
      <origin
        xyz="-5.55111512312578E-17 1.66533453693773E-16 0"
        rpy="0 0 0" />
      <mass
        value="0.163581158676094" />
      <inertia
        ixx="7.86654976191722E-05"
        ixy="1.62147635876547E-36"
        ixz="-2.92725644003597E-37"
        iyy="7.86654976191722E-05"
        iyz="5.87747175411144E-37"
        izz="0.000117962463050298" />
    </inertial>
    <visual>
      <origin
        xyz="0 0 0"
        rpy="0 0 0" />
      <geometry>
        <mesh
          filename="package://rohm_amr_description/meshes/caster_wheel_front_right_link.STL" />
      </geometry>
      <material
        name="">
        <color
          rgba="0.792156862745098 0.819607843137255 0.933333333333333 1" />
      </material>
    </visual>
    <collision>
      <origin
        xyz="0 0 0"
        rpy="0 0 0" />
      <geometry>
        <mesh
          filename="package://rohm_amr_description/meshes/caster_wheel_front_right_link.STL" />
      </geometry>
    </collision>
  </link>
  <joint
    name="caster_wheel_front_right_joint"
    type="continuous">
    <origin
      xyz="-0.043 0 -0.0695"
      rpy="1.5708 0 0" />
    <parent
      link="caster_arm_front_right_link" />
    <child
      link="caster_wheel_front_right_link" />
    <axis
      xyz="0 0 -1" />
  </joint>
  <link
    name="caster_arm_front_left_link">
    <inertial>
      <origin
        xyz="-0.00675421782324331 2.14599993331177E-09 -0.0243102631444927"
        rpy="0 0 0" />
      <mass
        value="0.102241293550996" />
      <inertia
        ixx="8.05168632706418E-05"
        ixy="3.11393169037364E-12"
        ixz="-2.07659739353893E-05"
        iyy="8.44086372703286E-05"
        iyz="-3.5715355661517E-12"
        izz="6.67184713176472E-05" />
    </inertial>
    <visual>
      <origin
        xyz="0 0 0"
        rpy="0 0 0" />
      <geometry>
        <mesh
          filename="package://rohm_amr_description/meshes/caster_arm_front_left_link.STL" />
      </geometry>
      <material
        name="">
        <color
          rgba="0.792156862745098 0.819607843137255 0.933333333333333 1" />
      </material>
    </visual>
    <collision>
      <origin
        xyz="0 0 0"
        rpy="0 0 0" />
      <geometry>
        <mesh
          filename="package://rohm_amr_description/meshes/caster_arm_front_left_link.STL" />
      </geometry>
    </collision>
  </link>
  <joint
    name="caster_arm_front_left_joint"
    type="continuous">
    <origin
      xyz="0.3775 0.16 0.107"
      rpy="0 0 0" />
    <parent
      link="base_link" />
    <child
      link="caster_arm_front_left_link" />
    <axis
      xyz="0 0 1" />
  </joint>
  <link
    name="caster_wheel_front_left_link">
    <inertial>
      <origin
        xyz="1.77635683940025E-15 1.73472347597681E-16 0"
        rpy="0 0 0" />
      <mass
        value="0.163581158676094" />
      <inertia
        ixx="7.86654976191722E-05"
        ixy="5.90881358212249E-40"
        ixz="-2.92725644003597E-37"
        iyy="7.86654976191722E-05"
        iyz="2.3706706348981E-37"
        izz="0.000117962463050298" />
    </inertial>
    <visual>
      <origin
        xyz="0 0 0"
        rpy="0 0 0" />
      <geometry>
        <mesh
          filename="package://rohm_amr_description/meshes/caster_wheel_front_left_link.STL" />
      </geometry>
      <material
        name="">
        <color
          rgba="0.792156862745098 0.819607843137255 0.933333333333333 1" />
      </material>
    </visual>
    <collision>
      <origin
        xyz="0 0 0"
        rpy="0 0 0" />
      <geometry>
        <mesh
          filename="package://rohm_amr_description/meshes/caster_wheel_front_left_link.STL" />
      </geometry>
    </collision>
  </link>
  <joint
    name="caster_wheel_front_left_joint"
    type="continuous">
    <origin
      xyz="-0.043 0 -0.0695"
      rpy="1.5708 0 0" />
    <parent
      link="caster_arm_front_left_link" />
    <child
      link="caster_wheel_front_left_link" />
    <axis
      xyz="0 0 -1" />
  </joint>
  <link
    name="caster_arm_rear_right_link">
    <inertial>
      <origin
        xyz="-0.00675421782323943 2.1460000165785E-09 -0.0243102631444928"
        rpy="0 0 0" />
      <mass
        value="0.102241293550996" />
      <inertia
        ixx="8.0516863270642E-05"
        ixy="3.11393170052989E-12"
        ixz="-2.07659739353893E-05"
        iyy="8.44086372703287E-05"
        iyz="-3.57153563380424E-12"
        izz="6.67184713176472E-05" />
    </inertial>
    <visual>
      <origin
        xyz="0 0 0"
        rpy="0 0 0" />
      <geometry>
        <mesh
          filename="package://rohm_amr_description/meshes/caster_arm_rear_right_link.STL" />
      </geometry>
      <material
        name="">
        <color
          rgba="0.792156862745098 0.819607843137255 0.933333333333333 1" />
      </material>
    </visual>
    <collision>
      <origin
        xyz="0 0 0"
        rpy="0 0 0" />
      <geometry>
        <mesh
          filename="package://rohm_amr_description/meshes/caster_arm_rear_right_link.STL" />
      </geometry>
    </collision>
  </link>
  <joint
    name="caster_arm_rear_right_joint"
    type="continuous">
    <origin
      xyz="-0.3775 -0.16 0.107"
      rpy="0 0 0" />
    <parent
      link="base_link" />
    <child
      link="caster_arm_rear_right_link" />
    <axis
      xyz="0 0 1" />
  </joint>
  <link
    name="caster_wheel_rear_right_link">
    <inertial>
      <origin
        xyz="-5.55111512312578E-17 -6.93889390390723E-18 0"
        rpy="0 0 0" />
      <mass
        value="0.163581158676094" />
      <inertia
        ixx="7.86654976191722E-05"
        ixy="-1.62029459604904E-36"
        ixz="-2.92725644003597E-37"
        iyy="7.86654976191722E-05"
        iyz="-5.87747175411144E-37"
        izz="0.000117962463050298" />
    </inertial>
    <visual>
      <origin
        xyz="0 0 0"
        rpy="0 0 0" />
      <geometry>
        <mesh
          filename="package://rohm_amr_description/meshes/caster_wheel_rear_right_link.STL" />
      </geometry>
      <material
        name="">
        <color
          rgba="0.792156862745098 0.819607843137255 0.933333333333333 1" />
      </material>
    </visual>
    <collision>
      <origin
        xyz="0 0 0"
        rpy="0 0 0" />
      <geometry>
        <mesh
          filename="package://rohm_amr_description/meshes/caster_wheel_rear_right_link.STL" />
      </geometry>
    </collision>
  </link>
  <joint
    name="caster_wheel_rear_right_joint"
    type="continuous">
    <origin
      xyz="-0.043 0.001 -0.0695"
      rpy="1.5708 0 0" />
    <parent
      link="caster_arm_rear_right_link" />
    <child
      link="caster_wheel_rear_right_link" />
    <axis
      xyz="0 0 -1" />
  </joint>
  <link
    name="caster_arm_rear_left_link">
    <inertial>
      <origin
        xyz="-0.00675421782325275 2.14600004433407E-09 -0.0243102631444927"
        rpy="0 0 0" />
      <mass
        value="0.102241293550996" />
      <inertia
        ixx="8.05168632706417E-05"
        ixy="3.11393167007536E-12"
        ixz="-2.07659739353893E-05"
        iyy="8.44086372703285E-05"
        iyz="-3.57153547612517E-12"
        izz="6.67184713176471E-05" />
    </inertial>
    <visual>
      <origin
        xyz="0 0 0"
        rpy="0 0 0" />
      <geometry>
        <mesh
          filename="package://rohm_amr_description/meshes/caster_arm_rear_left_link.STL" />
      </geometry>
      <material
        name="">
        <color
          rgba="0.792156862745098 0.819607843137255 0.933333333333333 1" />
      </material>
    </visual>
    <collision>
      <origin
        xyz="0 0 0"
        rpy="0 0 0" />
      <geometry>
        <mesh
          filename="package://rohm_amr_description/meshes/caster_arm_rear_left_link.STL" />
      </geometry>
    </collision>
  </link>
  <joint
    name="caster_arm_rear_left_joint"
    type="continuous">
    <origin
      xyz="-0.3775 0.16 0.107"
      rpy="0 0 0" />
    <parent
      link="base_link" />
    <child
      link="caster_arm_rear_left_link" />
    <axis
      xyz="0 0 1" />
  </joint>
  <link
    name="caster_wheel_rear_left_link">
    <inertial>
      <origin
        xyz="-3.44169137633799E-15 1.16989751219876E-14 0"
        rpy="0 0 0" />
      <mass
        value="0.163581158676094" />
      <inertia
        ixx="7.86654976191722E-05"
        ixy="5.90881358212249E-40"
        ixz="-2.92725644003597E-37"
        iyy="7.86654976191722E-05"
        iyz="2.3706706348981E-37"
        izz="0.000117962463050298" />
    </inertial>
    <visual>
      <origin
        xyz="0 0 0"
        rpy="0 0 0" />
      <geometry>
        <mesh
          filename="package://rohm_amr_description/meshes/caster_wheel_rear_left_link.STL" />
      </geometry>
      <material
        name="">
        <color
          rgba="0.792156862745098 0.819607843137255 0.933333333333333 1" />
      </material>
    </visual>
    <collision>
      <origin
        xyz="0 0 0"
        rpy="0 0 0" />
      <geometry>
        <mesh
          filename="package://rohm_amr_description/meshes/caster_wheel_rear_left_link.STL" />
      </geometry>
    </collision>
  </link>
  <joint
    name="caster_wheel_rear_left_joint"
    type="continuous">
    <origin
      xyz="-0.043 0 -0.0695"
      rpy="1.5708 0 0" />
    <parent
      link="caster_arm_rear_left_link" />
    <child
      link="caster_wheel_rear_left_link" />
    <axis
      xyz="0 0 -1" />
  </joint>
  <link
    name="imu_link">
    <inertial>
      <origin
        xyz="0.00372314733869097 -2.49899340665216E-08 0.000837508635019801"
        rpy="0 0 0" />
      <mass
        value="0.000502288061214731" />
      <inertia
        ixx="1.37978316417245E-08"
        ixy="1.26534574459438E-13"
        ixz="5.16668935382629E-11"
        iyy="1.30397927506381E-08"
        iyz="9.96944209839807E-15"
        izz="2.65859794426441E-08" />
    </inertial>
    <visual>
      <origin
        xyz="0 0 0"
        rpy="0 0 0" />
      <geometry>
        <mesh
          filename="package://rohm_amr_description/meshes/imu_link.STL" />
      </geometry>
      <material
        name="">
        <color
          rgba="0.792156862745098 0.819607843137255 0.933333333333333 1" />
      </material>
    </visual>
    <collision>
      <origin
        xyz="0 0 0"
        rpy="0 0 0" />
      <geometry>
        <mesh
          filename="package://rohm_amr_description/meshes/imu_link.STL" />
      </geometry>
    </collision>
  </link>
  <joint
    name="imu_joint"
    type="fixed">
    <origin
      xyz="0.13248 0.011901 0.26051"
      rpy="0 0 -1.5708" />
    <parent
      link="base_link" />
    <child
      link="imu_link" />
    <axis
      xyz="0 0 0" />
  </joint>
  <link
    name="lidar_front_right_roll_link">
    <inertial>
      <origin
        xyz="0.00341569824852672 -3.60822483003176E-16 0.000714686858124397"
        rpy="0 0 0" />
      <mass
        value="0.105074031653967" />
      <inertia
        ixx="0.000118386129259021"
        ixy="-3.59141969635823E-19"
        ixz="4.01713979224373E-06"
        iyy="3.27891394505926E-05"
        iyz="1.55848379328042E-20"
        izz="9.74424463210962E-05" />
    </inertial>
    <visual>
      <origin
        xyz="0 0 0"
        rpy="0 0 0" />
      <geometry>
        <mesh
          filename="package://rohm_amr_description/meshes/lidar_front_right_roll_link.STL" />
      </geometry>
      <material
        name="">
        <color
          rgba="0.792156862745098 0.792156862745098 0.792156862745098 1" />
      </material>
    </visual>
    <collision>
      <origin
        xyz="0 0 0"
        rpy="0 0 0" />
      <geometry>
        <mesh
          filename="package://rohm_amr_description/meshes/lidar_front_right_roll_link.STL" />
      </geometry>
    </collision>
  </link>
  <joint
    name="lidar_front_right_roll_joint"
    type="fixed">
    <origin
      xyz="0.39109 -0.15955 0.1745"
      rpy="0 0 -0.7854" />
    <parent
      link="base_link" />
    <child
      link="lidar_front_right_roll_link" />
    <axis
      xyz="0 0 0" />
  </joint>
  <link
    name="lidar_front_right_pitch_link">
    <inertial>
      <origin
        xyz="0.0289046048095006 1.11022302462516E-16 0.00388007864506032"
        rpy="0 0 0" />
      <mass
        value="0.143282605100291" />
      <inertia
        ixx="5.45047049148797E-05"
        ixy="-3.13402190484091E-19"
        ixz="-1.91335293827813E-05"
        iyy="0.000133259895991102"
        iyz="9.73323291802234E-20"
        izz="0.000160257762612893" />
    </inertial>
    <visual>
      <origin
        xyz="0 0 0"
        rpy="0 0 0" />
      <geometry>
        <mesh
          filename="package://rohm_amr_description/meshes/lidar_front_right_pitch_link.STL" />
      </geometry>
      <material
        name="">
        <color
          rgba="0.792156862745098 0.792156862745098 0.792156862745098 1" />
      </material>
    </visual>
    <collision>
      <origin
        xyz="0 0 0"
        rpy="0 0 0" />
      <geometry>
        <mesh
          filename="package://rohm_amr_description/meshes/lidar_front_right_pitch_link.STL" />
      </geometry>
    </collision>
  </link>
  <joint
    name="lidar_front_right_pitch_joint"
    type="fixed">
    <origin
      xyz="0.013 0 0.005"
      rpy="0 0 0" />
    <parent
      link="lidar_front_right_roll_link" />
    <child
      link="lidar_front_right_pitch_link" />
    <axis
      xyz="0 0 0" />
  </joint>
  <link
    name="lidar_front_right_link">
    <inertial>
      <origin
        xyz="0.240092407845002 2.40047584587622E-09 -8.52892701927455E-06"
        rpy="0 0 0" />
      <mass
        value="399.487966204344" />
      <inertia
        ixx="174.35420763036"
        ixy="-1.85064052971029E-09"
        ixz="3.22011540266463E-06"
        iyy="90.2687564368381"
        iyz="-8.07688384801051E-09"
        izz="264.607976285177" />
    </inertial>
    <visual>
      <origin
        xyz="0 0 0"
        rpy="0 0 0" />
      <geometry>
        <mesh
          filename="package://rohm_amr_description/meshes/lidar_front_right_link.STL" />
      </geometry>
      <material
        name="">
        <color
          rgba="1 0.501960784313725 0.501960784313725 1" />
      </material>
    </visual>
    <collision>
      <origin
        xyz="0 0 0"
        rpy="0 0 0" />
      <geometry>
        <mesh
          filename="package://rohm_amr_description/meshes/lidar_front_right_link.STL" />
      </geometry>
    </collision>
  </link>
  <joint
    name="lidar_front_right_joint"
    type="fixed">
    <origin
      xyz="0.055 0 -0.02135"
      rpy="3.1416 0 0" />
    <parent
      link="lidar_front_right_pitch_link" />
    <child
      link="lidar_front_right_link" />
    <axis
      xyz="0 0 0" />
  </joint>
  <link
    name="lidar_rear_left_roll_link">
    <inertial>
      <origin
        xyz="0.00341569824853388 -1.11022302462516E-16 0.000714686858121899"
        rpy="0 0 0" />
      <mass
        value="0.105074031653967" />
      <inertia
        ixx="0.000118386129259021"
        ixy="-1.84653182501437E-19"
        ixz="4.01713979224373E-06"
        iyy="3.27891394505925E-05"
        iyz="2.00196805380229E-19"
        izz="9.74424463210963E-05" />
    </inertial>
    <visual>
      <origin
        xyz="0 0 0"
        rpy="0 0 0" />
      <geometry>
        <mesh
          filename="package://rohm_amr_description/meshes/lidar_rear_left_roll_link.STL" />
      </geometry>
      <material
        name="">
        <color
          rgba="0.792156862745098 0.792156862745098 0.792156862745098 1" />
      </material>
    </visual>
    <collision>
      <origin
        xyz="0 0 0"
        rpy="0 0 0" />
      <geometry>
        <mesh
          filename="package://rohm_amr_description/meshes/lidar_rear_left_roll_link.STL" />
      </geometry>
    </collision>
  </link>
  <joint
    name="lidar_rear_left_roll_joint"
    type="fixed">
    <origin
      xyz="-0.37409 0.15955 0.1745"
      rpy="0 0 2.3562" />
    <parent
      link="base_link" />
    <child
      link="lidar_rear_left_roll_link" />
    <axis
      xyz="0 0 0" />
  </joint>
  <link
    name="lidar_rear_left_pitch_link">
    <inertial>
      <origin
        xyz="0.0289046048095066 1.38777878078145E-16 0.00388007864505172"
        rpy="0 0 0" />
      <mass
        value="0.143282605100291" />
      <inertia
        ixx="5.45047049148801E-05"
        ixy="-4.16740210049116E-19"
        ixz="-1.91335293827814E-05"
        iyy="0.000133259895991102"
        iyz="1.56465740326953E-20"
        izz="0.000160257762612894" />
    </inertial>
    <visual>
      <origin
        xyz="0 0 0"
        rpy="0 0 0" />
      <geometry>
        <mesh
          filename="package://rohm_amr_description/meshes/lidar_rear_left_pitch_link.STL" />
      </geometry>
      <material
        name="">
        <color
          rgba="0.792156862745098 0.792156862745098 0.792156862745098 1" />
      </material>
    </visual>
    <collision>
      <origin
        xyz="0 0 0"
        rpy="0 0 0" />
      <geometry>
        <mesh
          filename="package://rohm_amr_description/meshes/lidar_rear_left_pitch_link.STL" />
      </geometry>
    </collision>
  </link>
  <joint
    name="lidar_rear_left_pitch_joint"
    type="fixed">
    <origin
      xyz="0.013 0 0.005"
      rpy="0 0 0" />
    <parent
      link="lidar_rear_left_roll_link" />
    <child
      link="lidar_rear_left_pitch_link" />
    <axis
      xyz="0 0 0" />
  </joint>
  <link
    name="lidar_rear_left_link">
    <inertial>
      <origin
        xyz="0.240092407844441 2.40045899824182E-09 -8.52892705119346E-06"
        rpy="0 0 0" />
      <mass
        value="399.487966205156" />
      <inertia
        ixx="174.35420763036"
        ixy="-1.85067605684708E-09"
        ixz="3.22011540523997E-06"
        iyy="90.2687564368381"
        iyz="-8.07682181755778E-09"
        izz="264.607976285178" />
    </inertial>
    <visual>
      <origin
        xyz="0 0 0"
        rpy="0 0 0" />
      <geometry>
        <mesh
          filename="package://rohm_amr_description/meshes/lidar_rear_left_link.STL" />
      </geometry>
      <material
        name="">
        <color
          rgba="1 0.501960784313725 0.501960784313725 1" />
      </material>
    </visual>
    <collision>
      <origin
        xyz="0 0 0"
        rpy="0 0 0" />
      <geometry>
        <mesh
          filename="package://rohm_amr_description/meshes/lidar_rear_left_link.STL" />
      </geometry>
    </collision>
  </link>
  <joint
    name="lidar_rear_left_joint"
    type="fixed">
    <origin
      xyz="0.055 0 -0.02135"
      rpy="3.1416 0 0" />
    <parent
      link="lidar_rear_left_pitch_link" />
    <child
      link="lidar_rear_left_link" />
    <axis
      xyz="0 0 0" />
  </joint>
  <link
    name="lidar_merged_link">
    <inertial>
      <origin
        xyz="0.00324062163584135 -0.000226459164535731 0.00887925143437091"
        rpy="0 0 0" />
      <mass
        value="923.219933749901" />
      <inertia
        ixx="384.015226592815"
        ixy="96.9074498454372"
        ixz="-1.43120298898605"
        iyy="565.041215401844"
        iyz="-0.0259486902638359"
        izz="942.342649416445" />
    </inertial>
    <visual>
      <origin
        xyz="0 0 0"
        rpy="0 0 0" />
      <geometry>
        <mesh
          filename="package://rohm_amr_description/meshes/lidar_merged_link.STL" />
      </geometry>
      <material
        name="">
        <color
          rgba="1 1 1 1" />
      </material>
    </visual>
    <collision>
      <origin
        xyz="0 0 0"
        rpy="0 0 0" />
      <geometry>
        <mesh
          filename="package://rohm_amr_description/meshes/lidar_merged_link.STL" />
      </geometry>
    </collision>
  </link>
  <joint
    name="lidar_merge_joint"
    type="fixed">
    <origin
      xyz="0 0 0.15815"
      rpy="0 0 0" />
    <parent
      link="base_link" />
    <child
      link="lidar_merged_link" />
    <axis
      xyz="0 0 0" />
  </joint>
  <link
    name="depth_cam_mount_point_link">
    <inertial>
      <origin
        xyz="0.00153205265950423 0.00137950775247242 0.0124766239393624"
        rpy="0 0 0" />
      <mass
        value="0.286307538979572" />
      <inertia
        ixx="0.000183723814872738"
        ixy="-1.07569994202486E-06"
        ixz="7.99476012688966E-08"
        iyy="2.75127610571264E-05"
        iyz="1.19800096606718E-08"
        izz="0.00018535136318658" />
    </inertial>
    <visual>
      <origin
        xyz="0 0 0"
        rpy="0 0 0" />
      <geometry>
        <mesh
          filename="package://rohm_amr_description/meshes/depth_cam_mount_point_link.STL" />
      </geometry>
      <material
        name="">
        <color
          rgba="0.701960784313725 0.701960784313725 0.701960784313725 1" />
      </material>
    </visual>
    <collision>
      <origin
        xyz="0 0 0"
        rpy="0 0 0" />
      <geometry>
        <mesh
          filename="package://rohm_amr_description/meshes/depth_cam_mount_point_link.STL" />
      </geometry>
    </collision>
  </link>
  <joint
    name="depth_cam_mount_point_joint"
    type="fixed">
    <origin
      xyz="0.46771 0 0.10897"
      rpy="-0.0043513 -0.24431 0.017987" />
    <parent
      link="base_link" />
    <child
      link="depth_cam_mount_point_link" />
    <axis
      xyz="0 0 0" />
  </joint>
  <link
    name="ultrasonic_front_right_link">
    <inertial>
      <origin
        xyz="-0.0101951890574369 0.00176519904874645 -0.00093909748619353"
        rpy="0 0 0" />
      <mass
        value="0.00561297834512605" />
      <inertia
        ixx="2.110210056278E-07"
        ixy="-7.93292062270086E-10"
        ixz="2.66386687973336E-23"
        iyy="1.81264873897895E-07"
        iyz="1.57650879589313E-09"
        izz="1.53595696502951E-07" />
    </inertial>
    <visual>
      <origin
        xyz="0 0 0"
        rpy="0 0 0" />
      <geometry>
        <mesh
          filename="package://rohm_amr_description/meshes/ultrasonic_front_right_link.STL" />
      </geometry>
      <material
        name="">
        <color
          rgba="0.792156862745098 0.819607843137255 0.933333333333333 1" />
      </material>
    </visual>
    <collision>
      <origin
        xyz="0 0 0"
        rpy="0 0 0" />
      <geometry>
        <mesh
          filename="package://rohm_amr_description/meshes/ultrasonic_front_right_link.STL" />
      </geometry>
    </collision>
  </link>
  <joint
    name="ultrasonic_front_right_joint"
    type="fixed">
    <origin
      xyz="0.4935 -0.15575 0.127"
      rpy="0 0 0" />
    <parent
      link="base_link" />
    <child
      link="ultrasonic_front_right_link" />
    <axis
      xyz="0 0 0" />
  </joint>
  <link
    name="ultrasonic_front_right_side_link">
    <inertial>
      <origin
        xyz="-0.0101951890574369 0.00176519904874645 -0.000939097486193474"
        rpy="0 0 0" />
      <mass
        value="0.00561297834512607" />
      <inertia
        ixx="2.110210056278E-07"
        ixy="-7.93292062270125E-10"
        ixz="2.96117471129401E-24"
        iyy="1.81264873897896E-07"
        iyz="1.57650879589317E-09"
        izz="1.53595696502952E-07" />
    </inertial>
    <visual>
      <origin
        xyz="0 0 0"
        rpy="0 0 0" />
      <geometry>
        <mesh
          filename="package://rohm_amr_description/meshes/ultrasonic_front_right_side_link.STL" />
      </geometry>
      <material
        name="">
        <color
          rgba="0.792156862745098 0.819607843137255 0.933333333333333 1" />
      </material>
    </visual>
    <collision>
      <origin
        xyz="0 0 0"
        rpy="0 0 0" />
      <geometry>
        <mesh
          filename="package://rohm_amr_description/meshes/ultrasonic_front_right_side_link.STL" />
      </geometry>
    </collision>
  </link>
  <joint
    name="ultrasonic_front_right_side_link"
    type="fixed">
    <origin
      xyz="0.3975 -0.2525 0.127"
      rpy="0 0 -1.5708" />
    <parent
      link="base_link" />
    <child
      link="ultrasonic_front_right_side_link" />
    <axis
      xyz="0 0 0" />
  </joint>
  <link
    name="ultrasonic_front_left_link">
    <inertial>
      <origin
        xyz="-0.0101951890574369 -0.00176519904874642 0.000939097486193557"
        rpy="0 0 0" />
      <mass
        value="0.00561297834512606" />
      <inertia
        ixx="2.110210056278E-07"
        ixy="7.93292062270107E-10"
        ixz="1.7991825184055E-23"
        iyy="1.81264873897895E-07"
        iyz="1.57650879589309E-09"
        izz="1.53595696502952E-07" />
    </inertial>
    <visual>
      <origin
        xyz="0 0 0"
        rpy="0 0 0" />
      <geometry>
        <mesh
          filename="package://rohm_amr_description/meshes/ultrasonic_front_left_link.STL" />
      </geometry>
      <material
        name="">
        <color
          rgba="0.792156862745098 0.819607843137255 0.933333333333333 1" />
      </material>
    </visual>
    <collision>
      <origin
        xyz="0 0 0"
        rpy="0 0 0" />
      <geometry>
        <mesh
          filename="package://rohm_amr_description/meshes/ultrasonic_front_left_link.STL" />
      </geometry>
    </collision>
  </link>
  <joint
    name="ultrasonic_front_left_joint"
    type="fixed">
    <origin
      xyz="0.4935 0.15575 0.127"
      rpy="0 0 0" />
    <parent
      link="base_link" />
    <child
      link="ultrasonic_front_left_link" />
    <axis
      xyz="0 0 0" />
  </joint>
  <link
    name="ultrasonic_front_left_side_link">
    <inertial>
      <origin
        xyz="-0.0101951890574369 -0.0017651990487465 0.000939097486193557"
        rpy="0 0 0" />
      <mass
        value="0.00561297834512606" />
      <inertia
        ixx="2.110210056278E-07"
        ixy="7.93292062270289E-10"
        ixz="-1.19645295731153E-23"
        iyy="1.81264873897895E-07"
        iyz="1.57650879589315E-09"
        izz="1.53595696502952E-07" />
    </inertial>
    <visual>
      <origin
        xyz="0 0 0"
        rpy="0 0 0" />
      <geometry>
        <mesh
          filename="package://rohm_amr_description/meshes/ultrasonic_front_left_side_link.STL" />
      </geometry>
      <material
        name="">
        <color
          rgba="0.792156862745098 0.819607843137255 0.933333333333333 1" />
      </material>
    </visual>
    <collision>
      <origin
        xyz="0 0 0"
        rpy="0 0 0" />
      <geometry>
        <mesh
          filename="package://rohm_amr_description/meshes/ultrasonic_front_left_side_link.STL" />
      </geometry>
    </collision>
  </link>
  <joint
    name="ultrasonic_front_left_side_joint"
    type="fixed">
    <origin
      xyz="0.3975 0.2525 0.127"
      rpy="0 0 1.5708" />
    <parent
      link="base_link" />
    <child
      link="ultrasonic_front_left_side_link" />
    <axis
      xyz="0 0 0" />
  </joint>
  <link
    name="ultrasonic_rear_right_link">
    <inertial>
      <origin
        xyz="-0.0101951890574369 0.00176519904874642 -0.00093909748619353"
        rpy="0 0 0" />
      <mass
        value="0.00561297834512606" />
      <inertia
        ixx="2.110210056278E-07"
        ixy="-7.93292062270071E-10"
        ixz="3.6042828572772E-23"
        iyy="1.81264873897895E-07"
        iyz="1.5765087958931E-09"
        izz="1.53595696502951E-07" />
    </inertial>
    <visual>
      <origin
        xyz="0 0 0"
        rpy="0 0 0" />
      <geometry>
        <mesh
          filename="package://rohm_amr_description/meshes/ultrasonic_rear_right_link.STL" />
      </geometry>
      <material
        name="">
        <color
          rgba="0.792156862745098 0.819607843137255 0.933333333333333 1" />
      </material>
    </visual>
    <collision>
      <origin
        xyz="0 0 0"
        rpy="0 0 0" />
      <geometry>
        <mesh
          filename="package://rohm_amr_description/meshes/ultrasonic_rear_right_link.STL" />
      </geometry>
    </collision>
  </link>
  <joint
    name="ultrasonic_rear_right_joint"
    type="fixed">
    <origin
      xyz="-0.47 -0.1765 0.127"
      rpy="0 0 3.1416" />
    <parent
      link="base_link" />
    <child
      link="ultrasonic_rear_right_link" />
    <axis
      xyz="0 0 0" />
  </joint>
  <link
    name="ultrasonic_rear_right_side_link">
    <inertial>
      <origin
        xyz="-0.010195189057437 -0.00176519904874645 0.00093909748619353"
        rpy="0 0 0" />
      <mass
        value="0.00561297834512607" />
      <inertia
        ixx="2.110210056278E-07"
        ixy="7.93292062270207E-10"
        ixz="-1.23989478642897E-23"
        iyy="1.81264873897895E-07"
        iyz="1.57650879589313E-09"
        izz="1.53595696502952E-07" />
    </inertial>
    <visual>
      <origin
        xyz="0 0 0"
        rpy="0 0 0" />
      <geometry>
        <mesh
          filename="package://rohm_amr_description/meshes/ultrasonic_rear_right_side_link.STL" />
      </geometry>
      <material
        name="">
        <color
          rgba="0.792156862745098 0.819607843137255 0.933333333333333 1" />
      </material>
    </visual>
    <collision>
      <origin
        xyz="0 0 0"
        rpy="0 0 0" />
      <geometry>
        <mesh
          filename="package://rohm_amr_description/meshes/ultrasonic_rear_right_side_link.STL" />
      </geometry>
    </collision>
  </link>
  <joint
    name="ultrasonic_rear_right_side_joint"
    type="fixed">
    <origin
      xyz="-0.3975 -0.2525 0.127"
      rpy="0 0 -1.5708" />
    <parent
      link="base_link" />
    <child
      link="ultrasonic_rear_right_side_link" />
    <axis
      xyz="0 0 0" />
  </joint>
  <link
    name="ultrasonic_rear_left_link">
    <inertial>
      <origin
        xyz="-0.0101951890574368 -0.00176519904874645 0.00093909748619353"
        rpy="0 0 0" />
      <mass
        value="0.00561297834512605" />
      <inertia
        ixx="2.110210056278E-07"
        ixy="7.93292062270103E-10"
        ixz="7.20951036793589E-23"
        iyy="1.81264873897895E-07"
        iyz="1.57650879589312E-09"
        izz="1.53595696502951E-07" />
    </inertial>
    <visual>
      <origin
        xyz="0 0 0"
        rpy="0 0 0" />
      <geometry>
        <mesh
          filename="package://rohm_amr_description/meshes/ultrasonic_rear_left_link.STL" />
      </geometry>
      <material
        name="">
        <color
          rgba="0.792156862745098 0.819607843137255 0.933333333333333 1" />
      </material>
    </visual>
    <collision>
      <origin
        xyz="0 0 0"
        rpy="0 0 0" />
      <geometry>
        <mesh
          filename="package://rohm_amr_description/meshes/ultrasonic_rear_left_link.STL" />
      </geometry>
    </collision>
  </link>
  <joint
    name="ultrasonic_rear_left_joint"
    type="fixed">
    <origin
      xyz="-0.47 0.1765 0.127"
      rpy="0 0 3.1416" />
    <parent
      link="base_link" />
    <child
      link="ultrasonic_rear_left_link" />
    <axis
      xyz="0 0 0" />
  </joint>
  <link
    name="ultrasonic_rear_left_side_link">
    <inertial>
      <origin
        xyz="-0.0101951890574369 0.00176519904874639 -0.000939097486193502"
        rpy="0 0 0" />
      <mass
        value="0.00561297834512606" />
      <inertia
        ixx="2.110210056278E-07"
        ixy="-7.93292062270107E-10"
        ixz="-4.45319506719329E-23"
        iyy="1.81264873897895E-07"
        iyz="1.57650879589314E-09"
        izz="1.53595696502952E-07" />
    </inertial>
    <visual>
      <origin
        xyz="0 0 0"
        rpy="0 0 0" />
      <geometry>
        <mesh
          filename="package://rohm_amr_description/meshes/ultrasonic_rear_left_side_link.STL" />
      </geometry>
      <material
        name="">
        <color
          rgba="0.792156862745098 0.819607843137255 0.933333333333333 1" />
      </material>
    </visual>
    <collision>
      <origin
        xyz="0 0 0"
        rpy="0 0 0" />
      <geometry>
        <mesh
          filename="package://rohm_amr_description/meshes/ultrasonic_rear_left_side_link.STL" />
      </geometry>
    </collision>
  </link>
  <joint
    name="ultrasonic_rear_left_side_right"
    type="fixed">
    <origin
      xyz="-0.3975 0.2525 0.127"
      rpy="0 0 1.5708" />
    <parent
      link="base_link" />
    <child
      link="ultrasonic_rear_left_side_link" />
    <axis
      xyz="0 0 0" />
  </joint>
</robot>